<mujoco model="ReachBot">


    <body name="arm1" pos="0 0 0.5">
        <body name="Base1" pos="0 0 0">
            <geom name="Base1" size=".09 0.02515 0.0025" type="box" pos="0 0 0" rgba=".2 .2 .2 1" contype="1" conaffinity="5"/>
            <body name="Motor11" pos="0 0 0.069311">
                <joint name="revolver11" type="hinge" axis="0 0 1" damping="50"/>
                <geom name="Motor11" size="0.075 0.0381 0.055" type="box" pos="0 0 0" rgba="0.7 0.7 0.7 1" contype="2" conaffinity="5" mass="2.5"/>
                <body name="Motor12" pos="0 0 0.036176">
                    <site name="motorSiteA1" pos="0 0 -0.0525" size="0.0001"/>
                    <site name="motorSiteB1" pos="0.025 0 -0.0525" size="0.0001"/>
                    <site name="motorSiteC1" pos="-0.025 0 -0.0525" size="0.0001"/>
                    <geom name="Motor12" size="0.06313 0.0605" pos="0 0.0158975 0" quat="0.7071 0 0.7071 0" type="cylinder" rgba="0.5 0 0 1" contype="3" conaffinity="5" mass="2.5"/>
                    <joint name="revolver12" type="hinge" range="0 3.2" axis="1 0 0" pos="0 0 0" damping="50"/>
                    <body name="boom1" pos="0 0.079837 -0.0525">
                        <geom name="boom1" size="0.025" type="sphere" rgba="0.5 0 0 1" contype="4" conaffinity="5" friction="0.1 0 0" mass="1.0"/>
                        <joint name="prismatic1" type="slide" range="0 3.048" axis="0 1 0" damping="40"/>
                        <site name="boomSiteA1" pos="0 0 0" size="0.0001"/>
                    </body>
                </body>
            </body>
        </body>
    </body>

</mujoco>
