<mujoco model="ReachBot">

    <visual>
        <map force="0.1" zfar="30"/>
        <rgba haze="0.15 0.25 0.35 1"/>
        <global offwidth="2560" offheight="1440" elevation="-20" azimuth="120"/>
    </visual>

    <statistic center="0 0 0.7"/>

    <asset>
        <texture type="skybox" builtin="gradient" rgb1=".3 .5 .7" rgb2="0 0 0" width="32" height="512"/>
        <texture name="body" type="cube" builtin="flat" mark="cross" width="128" height="128" rgb1="0.8 0.6 0.4" rgb2="0.8 0.6 0.4" markrgb="1 1 1"/>
        <material name="body" texture="body" texuniform="true" rgba="0.8 0.6 .4 1"/>
        <texture name="grid" type="2d" builtin="checker" width="512" height="512" rgb1=".1 .2 .3" rgb2=".2 .3 .4"/>
        <material name="grid" texture="grid" texrepeat="1 1" texuniform="true" reflectance="0"/>
    </asset>

    <worldbody>
        <light directional="true" pos="0 0 5" dir="0 0 -1"/>
        <geom name="floor" size="0 0 .05" type="plane" material="grid" contype="5" condim="3"/>

        <body name="mainBody" pos="0 0 0.5">
            <joint name="freejoint" type="free"/>
            <geom name="mainBody" type="box" size="0.09 0.09 0.02515" mass="1"/>

            <!-- Arm 1 -->
            <body name="arm1" pos="0 0.09 0" euler="-90 0 0">
                <body name="Base1" pos="0 0 0">
                    <geom name="Base1" size=".09 0.02515 0.0025" type="box" pos="0 0 0" rgba="0 .8 0 1" contype="1" conaffinity="5"/>
                    <body name="Motor11" pos="0 0 0.069311">
                        <joint name="revolver11" type="hinge" axis="0 0 1" damping="50"/>
                        <geom name="Motor11" size="0.075 0.0381 0.055" type="box" pos="0 0 0" rgba="0.7 0.7 0.7 1" contype="2" conaffinity="5" mass="0.377"/>
                        <body name="Motor12" pos="0 0 0.036176">
                            <geom name="Motor12" size="0.06313 0.0605" pos="0 0.0158975 0" euler="0 90 0" type="cylinder" rgba="0 0 1 1" contype="3" conaffinity="5" mass="1.046"/>
                            <joint name="revolver12" type="hinge" axis="1 0 0" pos="0 0 0" damping="50"/>
                            
    <site name="boomSiteA1" pos="0 0.034837 0" size="0.0001"/>
    <site name="boomSiteB1" pos="0.025 0.034837 0" size="0.0001"/>
    <site name="boomSiteC1" pos="-0.025 0.034837 0" size="0.0001"/>
                                <geom name="boom1" size="0.05" type="sphere" rgba="0.1 0.1 0.1 1" contype="4" conaffinity="5" friction="0.1 0 0" mass="0.344"/>
                                <joint name="prismatic1" type="slide" axis="0 1 0" damping="40"/>
                            </body>
                        </body>
                    </body>
                </body>
            </body>
        </body>
    </worldbody>

    <actuator>
        <position name="motor11p" joint="revolver11" kp="800" ctrlrange="-3.2 3.2" forcelimited="true" forcerange="-25 25"/>
        <position name="motor12p" joint="revolver12" kp="800" ctrlrange="0 3.2" forcelimited="true" forcerange="-25 25"/>
        <position name="motor13p" joint="prismatic1" kp="1000" ctrlrange="0 1.7" forcelimited="true" forcerange="-476 476"/>
    </actuator>

    <tendon>
        <spatial name="boomvisualA1" width=".01" rgba="0.1 0.1 0.1 1">
            <site site="boomSiteA1"/>
            <site site="motorSiteA1"/>
        </spatial>
        <spatial name="boomvisualB1" width=".01" rgba="0.1 0.1 0.1 1">
            <site site="boomSiteB1"/>
            <site site="motorSiteB1"/>
        </spatial>
        <spatial name="boomvisualC1" width=".01" rgba="0.1 0.1 0.1 1">
            <site site="boomSiteC1"/>
            <site site="motorSiteC1"/>
        </spatial>
    </tendon>

</mujoco>